Workbook

Sheet Agenda Planner
A1: FTI CONNECT / SEMINAR AGENDA PLANNER
A2: ใช้วางโครงงานอบรม/สัมมนาแบบ Experience: เลือกหัวข้อ → ระบบดึง Detail → ใส่เวลา → สรุปเวลารวมอัตโนมัติ
A3: ชื่องาน | B3: FTI CONNECT 2026 | D3: จำนวนหัวข้อที่ใช้ | E3: =COUNTA(C11:C80) -> 15 | G3: สีหมวดหัวข้อ / อ่าน agenda เร็วขึ้น
A4: วันที่จัดงาน | B4: 46272 | D4: เวลารวมทั้งหมด (นาที) | E4: =SUM(H11:H80) -> 475 | G4: Corporate | H4: Product | I4: Membership | J4: Branch | K4: Customer | L4: Interactive | M4: Recognition | N4: Logistics | O4: Entertainment | P4: Marketing
A5: กลุ่มเป้าหมายหลัก | B5: Dealer ทั่วไป | D5: เวลารวม (ชั่วโมง) | E5: =IFERROR(E4/60,"") -> 7.9166667 | G5: ทิศทาง | H5: สินค้า | I5: ระบบสมาชิก/ดิจิทัล | J5: สาขา | K5: เสียงลูกค้า | L5: มีส่วนร่วม | M5: รางวัล | N5: พัก/ลงทะเบียน | O5: กิจกรรม | P5: การตลาด
A6: จุดประสงค์หลัก | B6: อัปเดตทิศทาง FTI | D6: เริ่มเร็วสุด | E6: =IFERROR(MIN(F11:F80),"") -> 0.375 | G6: Tip: เลือกหัวข้อในคอลัมน์ C แล้วระบบจะดึงหมวด/รูปแบบ/Detail/จุดประสงค์ย่อยมาให้ ทีมสามารถปรับเวลา วิทยากร สถานะ และ Owner ได้ตามจริง
A7: หมายเหตุภาพรวม | D7: จบช้าสุด | E7: =IFERROR(MAX(G11:G80),"") -> 0.6875
A10: ลำดับ | B10: วันที่ | C10: หัวข้อ | D10: หมวด | E10: รูปแบบ | F10: เริ่ม | G10: จบ | H10: นาที | I10: วิทยากร | J10: สถานะ | K10: Detail อัตโนมัติ | L10: จุดประสงค์ย่อย / สิ่งที่ต้องสื่อ | M10: ผลลัพธ์ที่อยากได้กลับมา | N10: เหมาะกับกลุ่ม | O10: หมายเหตุทีม | P10: Owner / Follow-up
A11: =IF(C11="","",ROW()-10) -> 1 | B11: =IF(C11="","",IF($B$4="","",$B$4)) -> 46272 | C11: Registration | D11: {=IFERROR(XLOOKUP(C11,Data!$B$74:$B$122,Data!$A$74:$A$122,""),"")} -> Logistics | E11: Break | F11: =TIME(9,0,0) -> 0.375 | G11: =TIME(9,30,0) -> 0.39583333 | H11: =IF(OR(F11="",G11=""),"",ROUND((G11-F11)*1440,0)) -> 30 | I11: ทีม Marketing Content | J11: Confirmed | K11: {=IFERROR(XLOOKUP(C11,Data!$B$74:$B$122,Data!$F$74:$F$122,""),"")} -> ลงทะเบียน รับป้ายชื่อ เอกสาร และจัดกลุ่มผู้ร่วมงาน | L11: {=IFERROR(XLOOKUP(C11,Data!$B$74:$B$122,Data!$G$74:$G$122,""),"")} -> เริ่มงานเป็นระบบและเก็บข้อมูลผู้เข้าร่วม | M11: {=IFERROR(XLOOKUP(C11,Data!$B$74:$B$122,Data!$H$74:$H$122,""),"")} -> รายชื่อผู้เข้าร่วมจริงและกลุ่มเป้าหมาย | N11: {=IFERROR(XLOOKUP(C11,Data!$B$74:$B$122,Data!$I$74:$I$122,""),"")} -> Mixed Audience | O11: ลงทะเบียน + แจก QR/เอกสาร/แผนผังโซน
A12: =IF(C12="","",ROW()-10) -> 2 | B12: =IF(C12="","",IF($B$4="","",$B$4)) -> 46272 | C12: Opening & Welcome | D12: {=IFERROR(XLOOKUP(C12,Data!$B$74:$B$122,Data!$A$74:$A$122,""),"")} -> Corporate Update | E12: {=IFERROR(XLOOKUP(C12,Data!$B$74:$B$122,Data!$C$74:$C$122,""),"")} -> Keynote | F12: =TIME(9,30,0) -> 0.39583333 | G12: =TIME(9,40,0) -> 0.40277778 | H12: =IF(OR(F12="",G12=""),"",ROUND((G12-F12)*1440,0)) -> 10 | I12: {=IFERROR(XLOOKUP(C12,Data!$B$74:$B$122,Data!$E$74:$E$122,""),"")} -> Moderator | J12: Confirmed | K12: {=IFERROR(XLOOKUP(C12,Data!$B$74:$B$122,Data!$F$74:$F$122,""),"")} -> เปิดงาน สร้างบรรยากาศ และบอกเป้าหมายของวัน | L12: {=IFERROR(XLOOKUP(C12,Data!$B$74:$B$122,Data!$G$74:$G$122,""),"")} -> ให้ทุกคนเข้าใจว่างานนี้ไม่ใช่แค่ฟังอบรม แต่เป็นการร่วมวางทิศทาง | M12: {=IFERROR(XLOOKUP(C12,Data!$B$74:$B$122,Data!$H$74:$H$122,""),"")} -> ผู้ร่วมงานพร้อมเข้าสู่เนื้อหาและเข้าใจภาพรวม | N12: {=IFERROR(XLOOKUP(C12,Data!$B$74:$B$122,Data!$I$74:$I$122,""),"")} -> Mixed Audience | O12: เปิดกรอบงานว่าเป็น Experience ไม่ใช่สัมมนานั่งฟัง
A13: =IF(C13="","",ROW()-10) -> 3 | B13: =IF(C13="","",IF($B$4="","",$B$4)) -> 46272 | C13: CEO Vision Update | D13: {=IFERROR(XLOOKUP(C13,Data!$B$74:$B$122,Data!$A$74:$A$122,""),"")} -> Corporate Update | E13: {=IFERROR(XLOOKUP(C13,Data!$B$74:$B$122,Data!$C$74:$C$122,""),"")} -> Keynote | F13: =TIME(9,40,0) -> 0.40277778 | G13: =TIME(10,0,0) -> 0.41666667 | H13: =IF(OR(F13="",G13=""),"",ROUND((G13-F13)*1440,0)) -> 20 | I13: {=IFERROR(XLOOKUP(C13,Data!$B$74:$B$122,Data!$E$74:$E$122,""),"")} -> CEO | J13: Confirmed | K13: {=IFERROR(XLOOKUP(C13,Data!$B$74:$B$122,Data!$F$74:$F$122,""),"")} -> ผู้บริหารเล่าทิศทาง FTI ช่วงครบรอบ 30 ปี และการเปลี่ยนแปลงปีหน้า | L13: {=IFERROR(XLOOKUP(C13,Data!$B$74:$B$122,Data!$G$74:$G$122,""),"")} -> สร้างความเชื่อมั่นว่า FTI ไม่ได้หยุดนิ่งและพร้อมสนับสนุนทุกช่องทาง | M13: {=IFERROR(XLOOKUP(C13,Data!$B$74:$B$122,Data!$H$74:$H$122,""),"")} -> ความเชื่อมั่น/คำถามเชิงกลยุทธ์จากสาขาและ VIP | N13: {=IFERROR(XLOOKUP(C13,Data!$B$74:$B$122,Data!$I$74:$I$122,""),"")} -> 29 สาขา FTI | O13: ช่วงสร้างความมั่นใจ ควรเก็บภาพ PR
A14: =IF(C14="","",ROW()-10) -> 4 | B14: =IF(C14="","",IF($B$4="","",$B$4)) -> 46272 | C14: Membership Roadmap | D14: {=IFERROR(XLOOKUP(C14,Data!$B$74:$B$122,Data!$A$74:$A$122,""),"")} -> Membership & Digital | E14: {=IFERROR(XLOOKUP(C14,Data!$B$74:$B$122,Data!$C$74:$C$122,""),"")} -> Keynote | F14: =TIME(10,0,0) -> 0.41666667 | G14: =TIME(10,20,0) -> 0.43055556 | H14: =IF(OR(F14="",G14=""),"",ROUND((G14-F14)*1440,0)) -> 20 | I14: {=IFERROR(XLOOKUP(C14,Data!$B$74:$B$122,Data!$E$74:$E$122,""),"")} -> ผู้บริหารฝ่ายการตลาด | J14: Confirmed | K14: {=IFERROR(XLOOKUP(C14,Data!$B$74:$B$122,Data!$F$74:$F$122,""),"")} -> เล่า Roadmap ว่าระบบจะเต็ม 100% ปีหน้า แต่ทยอยเปิด Feature ก่อน | L14: {=IFERROR(XLOOKUP(C14,Data!$B$74:$B$122,Data!$G$74:$G$122,""),"")} -> ให้ Dealer/VIP เตรียมวางแผนการซื้อ ไม่ต้องรอถึงปีหน้า | M14: {=IFERROR(XLOOKUP(C14,Data!$B$74:$B$122,Data!$H$74:$H$122,""),"")} -> ความพร้อมเข้าร่วม Pilot และคำถามเงื่อนไข | N14: {=IFERROR(XLOOKUP(C14,Data!$B$74:$B$122,Data!$I$74:$I$122,""),"")} -> VIP Dealer | O14: เน้นว่า 100% ปีหน้า แต่ทยอยเปิดฟีเจอร์ให้ลองก่อน
A15: =IF(C15="","",ROW()-10) -> 5 | B15: =IF(C15="","",IF($B$4="","",$B$4)) -> 46272 | C15: Asset Drive Center Update | D15: {=IFERROR(XLOOKUP(C15,Data!$B$74:$B$122,Data!$A$74:$A$122,""),"")} -> Membership & Digital | E15: {=IFERROR(XLOOKUP(C15,Data!$B$74:$B$122,Data!$C$74:$C$122,""),"")} -> Demo / Playground | F15: =TIME(10,20,0) -> 0.43055556 | G15: =TIME(10,40,0) -> 0.44444444 | H15: =IF(OR(F15="",G15=""),"",ROUND((G15-F15)*1440,0)) -> 20 | I15: {=IFERROR(XLOOKUP(C15,Data!$B$74:$B$122,Data!$E$74:$E$122,""),"")} -> ทีม Marketing Content | J15: Confirmed | K15: {=IFERROR(XLOOKUP(C15,Data!$B$74:$B$122,Data!$F$74:$F$122,""),"")} -> อัปเดตศูนย์รวมรูปสินค้า Artwork Template คลิป และเอกสารขาย | L15: {=IFERROR(XLOOKUP(C15,Data!$B$74:$B$122,Data!$G$74:$G$122,""),"")} -> ให้สาขา/Dealer รู้ว่าหา Asset ได้จากที่ไหน ลดงานขอซ้ำ | M15: {=IFERROR(XLOOKUP(C15,Data!$B$74:$B$122,Data!$H$74:$H$122,""),"")} -> รายการ Asset ที่ต้องเพิ่มและผู้รับผิดชอบ | N15: {=IFERROR(XLOOKUP(C15,Data!$B$74:$B$122,Data!$I$74:$I$122,""),"")} -> 29 สาขา FTI | O15: สาธิตวิธีช่วยสาขา/Dealer ใช้รูปและสื่อขาย
A16: =IF(C16="","",ROW()-10) -> 6 | B16: =IF(C16="","",IF($B$4="","",$B$4)) -> 46272 | C16: Coffee Break | D16: {=IFERROR(XLOOKUP(C16,Data!$B$74:$B$122,Data!$A$74:$A$122,""),"")} -> Logistics | E16: {=IFERROR(XLOOKUP(C16,Data!$B$74:$B$122,Data!$C$74:$C$122,""),"")} -> Break | F16: =TIME(10,40,0) -> 0.44444444 | G16: =TIME(10,55,0) -> 0.45486111 | H16: =IF(OR(F16="",G16=""),"",ROUND((G16-F16)*1440,0)) -> 15 | I16: ทีม Marketing Content | J16: Confirmed | K16: {=IFERROR(XLOOKUP(C16,Data!$B$74:$B$122,Data!$F$74:$F$122,""),"")} -> พักเบรกและให้เดินชมโซนสินค้า/Asset/Membership | L16: {=IFERROR(XLOOKUP(C16,Data!$B$74:$B$122,Data!$G$74:$G$122,""),"")} -> ให้คนย่อยข้อมูลและสร้างบทสนทนาระหว่างกัน | M16: {=IFERROR(XLOOKUP(C16,Data!$B$74:$B$122,Data!$H$74:$H$122,""),"")} -> Feedback ระหว่างพักและการเยี่ยมโซน | N16: {=IFERROR(XLOOKUP(C16,Data!$B$74:$B$122,Data!$I$74:$I$122,""),"")} -> Mixed Audience | O16: ให้เดินดู Membership Zone / Product Zone
A17: =IF(C17="","",ROW()-10) -> 7 | B17: =IF(C17="","",IF($B$4="","",$B$4)) -> 46272 | C17: Hidden Gems Collection | D17: {=IFERROR(XLOOKUP(C17,Data!$B$74:$B$122,Data!$A$74:$A$122,""),"")} -> Product | E17: {=IFERROR(XLOOKUP(C17,Data!$B$74:$B$122,Data!$C$74:$C$122,""),"")} -> Demo / Playground | F17: =TIME(10,55,0) -> 0.45486111 | G17: =TIME(11,25,0) -> 0.47569444 | H17: =IF(OR(F17="",G17=""),"",ROUND((G17-F17)*1440,0)) -> 30 | I17: Product Manager | J17: Confirmed | K17: {=IFERROR(XLOOKUP(C17,Data!$B$74:$B$122,Data!$F$74:$F$122,""),"")} -> แนะนำสินค้าเก่าที่ดีแต่ไม่ค่อยถูกขาย พร้อมเหตุผลว่าทำไมควรหยิบมาขาย | L17: {=IFERROR(XLOOKUP(C17,Data!$B$74:$B$122,Data!$G$74:$G$122,""),"")} -> ปลุกสินค้า GP ดี/ปัญหาน้อย/ขายซ้ำได้ ให้กลับมาอยู่ในสายตา | M17: {=IFERROR(XLOOKUP(C17,Data!$B$74:$B$122,Data!$H$74:$H$122,""),"")} -> รายชื่อสินค้าที่สาขาอยากทดลองขาย | N17: {=IFERROR(XLOOKUP(C17,Data!$B$74:$B$122,Data!$I$74:$I$122,""),"")} -> Dealer ทั่วไป | O17: เลือกสินค้า 5-8 ตัวพอ อย่าเยอะเกิน
A18: =IF(C18="","",ROW()-10) -> 8 | B18: =IF(C18="","",IF($B$4="","",$B$4)) -> 46272 | C18: Hidden Gems Collection | D18: {=IFERROR(XLOOKUP(C18,Data!$B$74:$B$122,Data!$A$74:$A$122,""),"")} -> Product | E18: {=IFERROR(XLOOKUP(C18,Data!$B$74:$B$122,Data!$C$74:$C$122,""),"")} -> Demo / Playground | F18: =TIME(11,25,0) -> 0.47569444 | G18: =TIME(12,10,0) -> 0.50694444 | H18: =IF(OR(F18="",G18=""),"",ROUND((G18-F18)*1440,0)) -> 45 | I18: {=IFERROR(XLOOKUP(C18,Data!$B$74:$B$122,Data!$E$74:$E$122,""),"")} -> Product Manager | J18: Confirmed | K18: {=IFERROR(XLOOKUP(C18,Data!$B$74:$B$122,Data!$F$74:$F$122,""),"")} -> แนะนำสินค้าเก่าที่ดีแต่ไม่ค่อยถูกขาย พร้อมเหตุผลว่าทำไมควรหยิบมาขาย | L18: {=IFERROR(XLOOKUP(C18,Data!$B$74:$B$122,Data!$G$74:$G$122,""),"")} -> ปลุกสินค้า GP ดี/ปัญหาน้อย/ขายซ้ำได้ ให้กลับมาอยู่ในสายตา | M18: {=IFERROR(XLOOKUP(C18,Data!$B$74:$B$122,Data!$H$74:$H$122,""),"")} -> รายชื่อสินค้าที่สาขาอยากทดลองขาย | N18: {=IFERROR(XLOOKUP(C18,Data!$B$74:$B$122,Data!$I$74:$I$122,""),"")} -> Dealer ทั่วไป | O18: สินค้าใหม่ต้องจับได้/เห็นจริง
A19: =IF(C19="","",ROW()-10) -> 9 | B19: =IF(C19="","",IF($B$4="","",$B$4)) -> 46272 | C19: Lunch Break | D19: {=IFERROR(XLOOKUP(C19,Data!$B$74:$B$122,Data!$A$74:$A$122,""),"")} -> Logistics | E19: {=IFERROR(XLOOKUP(C19,Data!$B$74:$B$122,Data!$C$74:$C$122,""),"")} -> Lunch / Dinner | F19: =TIME(12,10,0) -> 0.50694444 | G19: =TIME(13,10,0) -> 0.54861111 | H19: =IF(OR(F19="",G19=""),"",ROUND((G19-F19)*1440,0)) -> 60 | I19: ทีม Marketing Content | J19: Confirmed | K19: {=IFERROR(XLOOKUP(C19,Data!$B$74:$B$122,Data!$F$74:$F$122,""),"")} -> พักกลางวัน พร้อมเปิดพื้นที่ Exhibition Zone | L19: {=IFERROR(XLOOKUP(C19,Data!$B$74:$B$122,Data!$G$74:$G$122,""),"")} -> ไม่ให้พลังงานตกและเพิ่มเวลาชมบูธ | M19: {=IFERROR(XLOOKUP(C19,Data!$B$74:$B$122,Data!$H$74:$H$122,""),"")} -> จำนวนคนเข้าโซนต่างๆ | N19: {=IFERROR(XLOOKUP(C19,Data!$B$74:$B$122,Data!$I$74:$I$122,""),"")} -> Mixed Audience | O19: เปิด Exhibition Zone ระหว่างพัก
A20: =IF(C20="","",ROW()-10) -> 10 | B20: =IF(C20="","",IF($B$4="","",$B$4)) -> 46272 | C20: Product Playground | D20: {=IFERROR(XLOOKUP(C20,Data!$B$74:$B$122,Data!$A$74:$A$122,""),"")} -> Interactive | E20: {=IFERROR(XLOOKUP(C20,Data!$B$74:$B$122,Data!$C$74:$C$122,""),"")} -> Demo / Playground | F20: =TIME(13,10,0) -> 0.54861111 | G20: =TIME(14,10,0) -> 0.59027778 | H20: =IF(OR(F20="",G20=""),"",ROUND((G20-F20)*1440,0)) -> 60 | I20: {=IFERROR(XLOOKUP(C20,Data!$B$74:$B$122,Data!$E$74:$E$122,""),"")} -> R&D | J20: Confirmed | K20: {=IFERROR(XLOOKUP(C20,Data!$B$74:$B$122,Data!$F$74:$F$122,""),"")} -> พื้นที่ทดลองสินค้าแบบหมุนฐาน ให้ผู้ร่วมงานจับ ลอง ถาม และเทียบได้ | L20: {=IFERROR(XLOOKUP(C20,Data!$B$74:$B$122,Data!$G$74:$G$122,""),"")} -> ทำให้สินค้าใหม่ถูกเข้าใจผ่านประสบการณ์ | M20: {=IFERROR(XLOOKUP(C20,Data!$B$74:$B$122,Data!$H$74:$H$122,""),"")} -> Feedback หน้างานและคำถามที่ต้องทำสื่อเพิ่ม | N20: {=IFERROR(XLOOKUP(C20,Data!$B$74:$B$122,Data!$I$74:$I$122,""),"")} -> Mixed Audience | O20: หมุนฐานทดลองสินค้า
A21: =IF(C21="","",ROW()-10) -> 11 | B21: =IF(C21="","",IF($B$4="","",$B$4)) -> 46272 | C21: Problem Solving Session | D21: {=IFERROR(XLOOKUP(C21,Data!$B$74:$B$122,Data!$A$74:$A$122,""),"")} -> Branch Sharing | E21: {=IFERROR(XLOOKUP(C21,Data!$B$74:$B$122,Data!$C$74:$C$122,""),"")} -> Clinic | F21: =TIME(14,10,0) -> 0.59027778 | G21: =TIME(14,40,0) -> 0.61111111 | H21: =IF(OR(F21="",G21=""),"",ROUND((G21-F21)*1440,0)) -> 30 | I21: {=IFERROR(XLOOKUP(C21,Data!$B$74:$B$122,Data!$E$74:$E$122,""),"")} -> Moderator | J21: Confirmed | K21: {=IFERROR(XLOOKUP(C21,Data!$B$74:$B$122,Data!$F$74:$F$122,""),"")} -> หยิบปัญหาจริงจากสาขามาช่วยกันแก้สด | L21: {=IFERROR(XLOOKUP(C21,Data!$B$74:$B$122,Data!$G$74:$G$122,""),"")} -> ทำให้การประชุมมีประโยชน์จริง ไม่ใช่แค่รับฟังจากส่วนกลาง | M21: {=IFERROR(XLOOKUP(C21,Data!$B$74:$B$122,Data!$H$74:$H$122,""),"")} -> รายการปัญหาและ Owner ที่ต้องกลับไปแก้ | N21: {=IFERROR(XLOOKUP(C21,Data!$B$74:$B$122,Data!$I$74:$I$122,""),"")} -> 29 สาขา FTI | O21: เลือก VIP ที่พูดเป็นประโยชน์และสร้างแรงบันดาลใจ
A22: =IF(C22="","",ROW()-10) -> 12 | B22: =IF(C22="","",IF($B$4="","",$B$4)) -> 46272 | C22: Coffee Break | D22: {=IFERROR(XLOOKUP(C22,Data!$B$74:$B$122,Data!$A$74:$A$122,""),"")} -> Logistics | E22: {=IFERROR(XLOOKUP(C22,Data!$B$74:$B$122,Data!$C$74:$C$122,""),"")} -> Break | F22: =TIME(14,40,0) -> 0.61111111 | G22: =TIME(14,55,0) -> 0.62152778 | H22: =IF(OR(F22="",G22=""),"",ROUND((G22-F22)*1440,0)) -> 15 | I22: ทีม Marketing Content | J22: Confirmed | K22: {=IFERROR(XLOOKUP(C22,Data!$B$74:$B$122,Data!$F$74:$F$122,""),"")} -> พักเบรกและให้เดินชมโซนสินค้า/Asset/Membership | L22: {=IFERROR(XLOOKUP(C22,Data!$B$74:$B$122,Data!$G$74:$G$122,""),"")} -> ให้คนย่อยข้อมูลและสร้างบทสนทนาระหว่างกัน | M22: {=IFERROR(XLOOKUP(C22,Data!$B$74:$B$122,Data!$H$74:$H$122,""),"")} -> Feedback ระหว่างพักและการเยี่ยมโซน | N22: {=IFERROR(XLOOKUP(C22,Data!$B$74:$B$122,Data!$I$74:$I$122,""),"")} -> Mixed Audience | O22: ใช้เคสจริงจากสาขา
A23: =IF(C23="","",ROW()-10) -> 13 | B23: =IF(C23="","",IF($B$4="","",$B$4)) -> 46272 | C23: New Product Showcase | D23: {=IFERROR(XLOOKUP(C23,Data!$B$74:$B$122,Data!$A$74:$A$122,""),"")} -> Product | E23: {=IFERROR(XLOOKUP(C23,Data!$B$74:$B$122,Data!$C$74:$C$122,""),"")} -> Demo / Playground | F23: =TIME(14,45,0) -> 0.61458333 | G23: =TIME(15,45,0) -> 0.65625 | H23: =IF(OR(F23="",G23=""),"",ROUND((G23-F23)*1440,0)) -> 60 | I23: {=IFERROR(XLOOKUP(C23,Data!$B$74:$B$122,Data!$E$74:$E$122,""),"")} -> Product Manager | J23: Confirmed | K23: {=IFERROR(XLOOKUP(C23,Data!$B$74:$B$122,Data!$F$74:$F$122,""),"")} -> เปิดตัวสินค้าใหม่แบบจับจริง เห็นจริง ไม่ใช่ดูสไลด์อย่างเดียว | L23: {=IFERROR(XLOOKUP(C23,Data!$B$74:$B$122,Data!$G$74:$G$122,""),"")} -> ทำให้ผู้ร่วมงานจำจุดขายและข้อจำกัดได้จริง | M23: {=IFERROR(XLOOKUP(C23,Data!$B$74:$B$122,Data!$H$74:$H$122,""),"")} -> Feedback ต่อสินค้าใหม่และการตั้งราคา/แพ็กเกจ | N23: {=IFERROR(XLOOKUP(C23,Data!$B$74:$B$122,Data!$I$74:$I$122,""),"")} -> VIP Dealer | O23: รอบละ 15 นาที 4 รอบ
A24: =IF(C24="","",ROW()-10) -> 14 | B24: =IF(C24="","",IF($B$4="","",$B$4)) -> 46272 | C24: Ask Me Anything | D24: {=IFERROR(XLOOKUP(C24,Data!$B$74:$B$122,Data!$A$74:$A$122,""),"")} -> Interactive | E24: {=IFERROR(XLOOKUP(C24,Data!$B$74:$B$122,Data!$C$74:$C$122,""),"")} -> Q&A | F24: =TIME(15,45,0) -> 0.65625 | G24: =TIME(16,15,0) -> 0.67708333 | H24: =IF(OR(F24="",G24=""),"",ROUND((G24-F24)*1440,0)) -> 30 | I24: {=IFERROR(XLOOKUP(C24,Data!$B$74:$B$122,Data!$E$74:$E$122,""),"")} -> Moderator | J24: Confirmed | K24: {=IFERROR(XLOOKUP(C24,Data!$B$74:$B$122,Data!$F$74:$F$122,""),"")} -> ถามตอบสดกับผู้บริหาร/ทีมหลักแบบควบคุมประเด็น | L24: {=IFERROR(XLOOKUP(C24,Data!$B$74:$B$122,Data!$G$74:$G$122,""),"")} -> เคลียร์ข้อสงสัยสำคัญก่อนปิดงาน | M24: {=IFERROR(XLOOKUP(C24,Data!$B$74:$B$122,Data!$H$74:$H$122,""),"")} -> FAQ และประเด็นที่ต้องสื่อสารต่อ | N24: {=IFERROR(XLOOKUP(C24,Data!$B$74:$B$122,Data!$I$74:$I$122,""),"")} -> Mixed Audience | O24: สรุปสิ่งที่จะทยอยเปิด + follow-up
A25: =IF(C25="","",ROW()-10) -> 15 | B25: =IF(C25="","",IF($B$4="","",$B$4)) -> 46272 | C25: Closing & Next Step | D25: {=IFERROR(XLOOKUP(C25,Data!$B$74:$B$122,Data!$A$74:$A$122,""),"")} -> Logistics | E25: {=IFERROR(XLOOKUP(C25,Data!$B$74:$B$122,Data!$C$74:$C$122,""),"")} -> Keynote | F25: =TIME(16,0,0) -> 0.66666667 | G25: =TIME(16,30,0) -> 0.6875 | H25: =IF(OR(F25="",G25=""),"",ROUND((G25-F25)*1440,0)) -> 30 | I25: {=IFERROR(XLOOKUP(C25,Data!$B$74:$B$122,Data!$E$74:$E$122,""),"")} -> ผู้บริหารฝ่ายการตลาด | J25: Confirmed | K25: {=IFERROR(XLOOKUP(C25,Data!$B$74:$B$122,Data!$F$74:$F$122,""),"")} -> สรุปสิ่งที่เกิดขึ้น สิ่งที่จะทยอยเปิด และช่องทางติดตามหลังงาน | L25: {=IFERROR(XLOOKUP(C25,Data!$B$74:$B$122,Data!$G$74:$G$122,""),"")} -> ปิดงานด้วย Action ไม่ใช่จบแล้วหาย | M25: {=IFERROR(XLOOKUP(C25,Data!$B$74:$B$122,Data!$H$74:$H$122,""),"")} -> รายการ Follow-up, Owner, Timeline | N25: {=IFERROR(XLOOKUP(C25,Data!$B$74:$B$122,Data!$I$74:$I$122,""),"")} -> Mixed Audience | O25: ใช้เฉพาะถ้างานเป็นครึ่งวันบ่ายถึงเย็น
A26: =IF(C26="","",ROW()-10) | B26: =IF(C26="","",IF($B$4="","",$B$4)) | D26: {=IFERROR(XLOOKUP(C26,Data!$B$74:$B$122,Data!$A$74:$A$122,""),"")} | E26: {=IFERROR(XLOOKUP(C26,Data!$B$74:$B$122,Data!$C$74:$C$122,""),"")} | H26: =IF(OR(F26="",G26=""),"",ROUND((G26-F26)*1440,0)) | I26: {=IFERROR(XLOOKUP(C26,Data!$B$74:$B$122,Data!$E$74:$E$122,""),"")} | K26: {=IFERROR(XLOOKUP(C26,Data!$B$74:$B$122,Data!$F$74:$F$122,""),"")} | L26: {=IFERROR(XLOOKUP(C26,Data!$B$74:$B$122,Data!$G$74:$G$122,""),"")} | M26: {=IFERROR(XLOOKUP(C26,Data!$B$74:$B$122,Data!$H$74:$H$122,""),"")} | N26: {=IFERROR(XLOOKUP(C26,Data!$B$74:$B$122,Data!$I$74:$I$122,""),"")}
A27: =IF(C27="","",ROW()-10) | B27: =IF(C27="","",IF($B$4="","",$B$4)) | D27: {=IFERROR(XLOOKUP(C27,Data!$B$74:$B$122,Data!$A$74:$A$122,""),"")} | E27: {=IFERROR(XLOOKUP(C27,Data!$B$74:$B$122,Data!$C$74:$C$122,""),"")} | H27: =IF(OR(F27="",G27=""),"",ROUND((G27-F27)*1440,0)) | I27: {=IFERROR(XLOOKUP(C27,Data!$B$74:$B$122,Data!$E$74:$E$122,""),"")} | K27: {=IFERROR(XLOOKUP(C27,Data!$B$74:$B$122,Data!$F$74:$F$122,""),"")} | L27: {=IFERROR(XLOOKUP(C27,Data!$B$74:$B$122,Data!$G$74:$G$122,""),"")} | M27: {=IFERROR(XLOOKUP(C27,Data!$B$74:$B$122,Data!$H$74:$H$122,""),"")} | N27: {=IFERROR(XLOOKUP(C27,Data!$B$74:$B$122,Data!$I$74:$I$122,""),"")}
A28: =IF(C28="","",ROW()-10) | B28: =IF(C28="","",IF($B$4="","",$B$4)) | D28: {=IFERROR(XLOOKUP(C28,Data!$B$74:$B$122,Data!$A$74:$A$122,""),"")} | E28: {=IFERROR(XLOOKUP(C28,Data!$B$74:$B$122,Data!$C$74:$C$122,""),"")} | H28: =IF(OR(F28="",G28=""),"",ROUND((G28-F28)*1440,0)) | I28: {=IFERROR(XLOOKUP(C28,Data!$B$74:$B$122,Data!$E$74:$E$122,""),"")} | K28: {=IFERROR(XLOOKUP(C28,Data!$B$74:$B$122,Data!$F$74:$F$122,""),"")} | L28: {=IFERROR(XLOOKUP(C28,Data!$B$74:$B$122,Data!$G$74:$G$122,""),"")} | M28: {=IFERROR(XLOOKUP(C28,Data!$B$74:$B$122,Data!$H$74:$H$122,""),"")} | N28: {=IFERROR(XLOOKUP(C28,Data!$B$74:$B$122,Data!$I$74:$I$122,""),"")}
A29: =IF(C29="","",ROW()-10) | B29: =IF(C29="","",IF($B$4="","",$B$4)) | D29: {=IFERROR(XLOOKUP(C29,Data!$B$74:$B$122,Data!$A$74:$A$122,""),"")} | E29: {=IFERROR(XLOOKUP(C29,Data!$B$74:$B$122,Data!$C$74:$C$122,""),"")} | H29: =IF(OR(F29="",G29=""),"",ROUND((G29-F29)*1440,0)) | I29: {=IFERROR(XLOOKUP(C29,Data!$B$74:$B$122,Data!$E$74:$E$122,""),"")} | K29: {=IFERROR(XLOOKUP(C29,Data!$B$74:$B$122,Data!$F$74:$F$122,""),"")} | L29: {=IFERROR(XLOOKUP(C29,Data!$B$74:$B$122,Data!$G$74:$G$122,""),"")} | M29: {=IFERROR(XLOOKUP(C29,Data!$B$74:$B$122,Data!$H$74:$H$122,""),"")} | N29: {=IFERROR(XLOOKUP(C29,Data!$B$74:$B$122,Data!$I$74:$I$122,""),"")}
A30: =IF(C30="","",ROW()-10) | B30: =IF(C30="","",IF($B$4="","",$B$4)) | D30: {=IFERROR(XLOOKUP(C30,Data!$B$74:$B$122,Data!$A$74:$A$122,""),"")} | E30: {=IFERROR(XLOOKUP(C30,Data!$B$74:$B$122,Data!$C$74:$C$122,""),"")} | H30: =IF(OR(F30="",G30=""),"",ROUND((G30-F30)*1440,0)) | I30: {=IFERROR(XLOOKUP(C30,Data!$B$74:$B$122,Data!$E$74:$E$122,""),"")} | K30: {=IFERROR(XLOOKUP(C30,Data!$B$74:$B$122,Data!$F$74:$F$122,""),"")} | L30: {=IFERROR(XLOOKUP(C30,Data!$B$74:$B$122,Data!$G$74:$G$122,""),"")} | M30: {=IFERROR(XLOOKUP(C30,Data!$B$74:$B$122,Data!$H$74:$H$122,""),"")} | N30: {=IFERROR(XLOOKUP(C30,Data!$B$74:$B$122,Data!$I$74:$I$122,""),"")}
A31: =IF(C31="","",ROW()-10) | B31: =IF(C31="","",IF($B$4="","",$B$4)) | D31: {=IFERROR(XLOOKUP(C31,Data!$B$74:$B$122,Data!$A$74:$A$122,""),"")} | E31: {=IFERROR(XLOOKUP(C31,Data!$B$74:$B$122,Data!$C$74:$C$122,""),"")} | H31: =IF(OR(F31="",G31=""),"",ROUND((G31-F31)*1440,0)) | I31: {=IFERROR(XLOOKUP(C31,Data!$B$74:$B$122,Data!$E$74:$E$122,""),"")} | K31: {=IFERROR(XLOOKUP(C31,Data!$B$74:$B$122,Data!$F$74:$F$122,""),"")} | L31: {=IFERROR(XLOOKUP(C31,Data!$B$74:$B$122,Data!$G$74:$G$122,""),"")} | M31: {=IFERROR(XLOOKUP(C31,Data!$B$74:$B$122,Data!$H$74:$H$122,""),"")} | N31: {=IFERROR(XLOOKUP(C31,Data!$B$74:$B$122,Data!$I$74:$I$122,""),"")}
A32: =IF(C32="","",ROW()-10) | B32: =IF(C32="","",IF($B$4="","",$B$4)) | D32: {=IFERROR(XLOOKUP(C32,Data!$B$74:$B$122,Data!$A$74:$A$122,""),"")} | E32: {=IFERROR(XLOOKUP(C32,Data!$B$74:$B$122,Data!$C$74:$C$122,""),"")} | H32: =IF(OR(F32="",G32=""),"",ROUND((G32-F32)*1440,0)) | I32: {=IFERROR(XLOOKUP(C32,Data!$B$74:$B$122,Data!$E$74:$E$122,""),"")} | K32: {=IFERROR(XLOOKUP(C32,Data!$B$74:$B$122,Data!$F$74:$F$122,""),"")} | L32: {=IFERROR(XLOOKUP(C32,Data!$B$74:$B$122,Data!$G$74:$G$122,""),"")} | M32: {=IFERROR(XLOOKUP(C32,Data!$B$74:$B$122,Data!$H$74:$H$122,""),"")} | N32: {=IFERROR(XLOOKUP(C32,Data!$B$74:$B$122,Data!$I$74:$I$122,""),"")}
A33: =IF(C33="","",ROW()-10) | B33: =IF(C33="","",IF($B$4="","",$B$4)) | D33: {=IFERROR(XLOOKUP(C33,Data!$B$74:$B$122,Data!$A$74:$A$122,""),"")} | E33: {=IFERROR(XLOOKUP(C33,Data!$B$74:$B$122,Data!$C$74:$C$122,""),"")} | H33: =IF(OR(F33="",G33=""),"",ROUND((G33-F33)*1440,0)) | I33: {=IFERROR(XLOOKUP(C33,Data!$B$74:$B$122,Data!$E$74:$E$122,""),"")} | K33: {=IFERROR(XLOOKUP(C33,Data!$B$74:$B$122,Data!$F$74:$F$122,""),"")} | L33: {=IFERROR(XLOOKUP(C33,Data!$B$74:$B$122,Data!$G$74:$G$122,""),"")} | M33: {=IFERROR(XLOOKUP(C33,Data!$B$74:$B$122,Data!$H$74:$H$122,""),"")} | N33: {=IFERROR(XLOOKUP(C33,Data!$B$74:$B$122,Data!$I$74:$I$122,""),"")}
A34: =IF(C34="","",ROW()-10) | B34: =IF(C34="","",IF($B$4="","",$B$4)) | D34: {=IFERROR(XLOOKUP(C34,Data!$B$74:$B$122,Data!$A$74:$A$122,""),"")} | E34: {=IFERROR(XLOOKUP(C34,Data!$B$74:$B$122,Data!$C$74:$C$122,""),"")} | H34: =IF(OR(F34="",G34=""),"",ROUND((G34-F34)*1440,0)) | I34: {=IFERROR(XLOOKUP(C34,Data!$B$74:$B$122,Data!$E$74:$E$122,""),"")} | K34: {=IFERROR(XLOOKUP(C34,Data!$B$74:$B$122,Data!$F$74:$F$122,""),"")} | L34: {=IFERROR(XLOOKUP(C34,Data!$B$74:$B$122,Data!$G$74:$G$122,""),"")} | M34: {=IFERROR(XLOOKUP(C34,Data!$B$74:$B$122,Data!$H$74:$H$122,""),"")} | N34: {=IFERROR(XLOOKUP(C34,Data!$B$74:$B$122,Data!$I$74:$I$122,""),"")}
A35: =IF(C35="","",ROW()-10) | B35: =IF(C35="","",IF($B$4="","",$B$4)) | D35: {=IFERROR(XLOOKUP(C35,Data!$B$74:$B$122,Data!$A$74:$A$122,""),"")} | E35: {=IFERROR(XLOOKUP(C35,Data!$B$74:$B$122,Data!$C$74:$C$122,""),"")} | H35: =IF(OR(F35="",G35=""),"",ROUND((G35-F35)*1440,0)) | I35: {=IFERROR(XLOOKUP(C35,Data!$B$74:$B$122,Data!$E$74:$E$122,""),"")} | K35: {=IFERROR(XLOOKUP(C35,Data!$B$74:$B$122,Data!$F$74:$F$122,""),"")} | L35: {=IFERROR(XLOOKUP(C35,Data!$B$74:$B$122,Data!$G$74:$G$122,""),"")} | M35: {=IFERROR(XLOOKUP(C35,Data!$B$74:$B$122,Data!$H$74:$H$122,""),"")} | N35: {=IFERROR(XLOOKUP(C35,Data!$B$74:$B$122,Data!$I$74:$I$122,""),"")}
A36: =IF(C36="","",ROW()-10) | B36: =IF(C36="","",IF($B$4="","",$B$4)) | D36: {=IFERROR(XLOOKUP(C36,Data!$B$74:$B$122,Data!$A$74:$A$122,""),"")} | E36: {=IFERROR(XLOOKUP(C36,Data!$B$74:$B$122,Data!$C$74:$C$122,""),"")} | H36: =IF(OR(F36="",G36=""),"",ROUND((G36-F36)*1440,0)) | I36: {=IFERROR(XLOOKUP(C36,Data!$B$74:$B$122,Data!$E$74:$E$122,""),"")} | K36: {=IFERROR(XLOOKUP(C36,Data!$B$74:$B$122,Data!$F$74:$F$122,""),"")} | L36: {=IFERROR(XLOOKUP(C36,Data!$B$74:$B$122,Data!$G$74:$G$122,""),"")} | M36: {=IFERROR(XLOOKUP(C36,Data!$B$74:$B$122,Data!$H$74:$H$122,""),"")} | N36: {=IFERROR(XLOOKUP(C36,Data!$B$74:$B$122,Data!$I$74:$I$122,""),"")}
A37: =IF(C37="","",ROW()-10) | B37: =IF(C37="","",IF($B$4="","",$B$4)) | D37: {=IFERROR(XLOOKUP(C37,Data!$B$74:$B$122,Data!$A$74:$A$122,""),"")} | E37: {=IFERROR(XLOOKUP(C37,Data!$B$74:$B$122,Data!$C$74:$C$122,""),"")} | H37: =IF(OR(F37="",G37=""),"",ROUND((G37-F37)*1440,0)) | I37: {=IFERROR(XLOOKUP(C37,Data!$B$74:$B$122,Data!$E$74:$E$122,""),"")} | K37: {=IFERROR(XLOOKUP(C37,Data!$B$74:$B$122,Data!$F$74:$F$122,""),"")} | L37: {=IFERROR(XLOOKUP(C37,Data!$B$74:$B$122,Data!$G$74:$G$122,""),"")} | M37: {=IFERROR(XLOOKUP(C37,Data!$B$74:$B$122,Data!$H$74:$H$122,""),"")} | N37: {=IFERROR(XLOOKUP(C37,Data!$B$74:$B$122,Data!$I$74:$I$122,""),"")}
... A80: =IF(C80="","",ROW()-10) | B80: =IF(C80="","",IF($B$4="","",$B$4)) | D80: {=IFERROR(XLOOKUP(C80,Data!$B$74:$B$122,Data!$A$74:$A$122,""),"")} | E80: {=IFERROR(XLOOKUP(C80,Data!$B$74:$B$122,Data!$C$74:$C$122,""),"")} | H80: =IF(OR(F80="",G80=""),"",ROUND((G80-F80)*1440,0)) | I80: {=IFERROR(XLOOKUP(C80,Data!$B$74:$B$122,Data!$E$74:$E$122,""),"")} | K80: {=IFERROR(XLOOKUP(C80,Data!$B$74:$B$122,Data!$F$74:$F$122,""),"")} | L80: {=IFERROR(XLOOKUP(C80,Data!$B$74:$B$122,Data!$G$74:$G$122,""),"")} | M80: {=IFERROR(XLOOKUP(C80,Data!$B$74:$B$122,Data!$H$74:$H$122,""),"")} | N80: {=IFERROR(XLOOKUP(C80,Data!$B$74:$B$122,Data!$I$74:$I$122,""),"")}

Sheet Data
A1: TargetGroups
A2: กลุ่มเป้าหมาย | B2: รายละเอียด
A3: 29 สาขา FTI | B3: ทีมหน้าร้าน/สาขาภายในทั้งหมด ใช้เพื่อสื่อสารทิศทางเดียวกัน
A4: VIP Dealer | B4: ตัวแทนจำหน่ายยอดสูง/มีอิทธิพล ควรเน้นความสัมพันธ์และสิทธิพิเศษ
A5: ลูกค้ารายใหญ่ที่ยังไม่เป็นตัวแทน | B5: ลูกค้าซื้อเยอะ แต่ยังไม่อยู่ในระบบ Dealer ใช้เพื่อปูทาง Partnership
A6: Dealer ทั่วไป | B6: กลุ่มตัวแทนกว้าง เน้นความเข้าใจระบบและโอกาสขาย
A7: ทีมขายภายใน | B7: Sale/Branch/Key Account ที่ต้องนำสารไปเล่าต่อ
A8: ผู้บริหารและหัวหน้าสาขา | B8: กลุ่มตัดสินใจ/วางแผน ให้เน้น Strategy และ Commitment
A9: Supplier Strategic | B9: Supplier ที่อยากให้ร่วมพัฒนา Product/Support
A10: Mixed Audience | B10: ใช้เมื่องานมีหลายกลุ่มรวมกัน ต้องบาลานซ์ความลึกของเนื้อหา
A13: MainObjectives
A14: จุดประสงค์หลัก | B14: รายละเอียด
A15: อัปเดตทิศทาง FTI | B15: สร้างความมั่นใจและภาพเดียวกันก่อนเริ่มปีใหม่
A16: เตรียมความพร้อมระบบ Membership | B16: ให้ผู้ร่วมงานเข้าใจแต้ม Tier และเริ่มวางแผนการซื้อ
A17: ประชาสัมพันธ์ Function Flow | B17: สื่อสารระบบ Tracking/Feature ที่จะทยอยเปิดใช้ก่อนเต็มรูปแบบ
A18: เปิดตัว/ทดลองสินค้าใหม่ | B18: ให้จับจริง เห็นจริง วางแผนขายได้ก่อนเปิดขาย
A19: ดันสินค้า Hidden Gems | B19: หยิบสินค้าดีที่ถูกมองข้ามกลับมาสร้างยอด
A20: รับฟังเสียงสาขาและ VIP | B20: เก็บ Insight ปัญหา ความต้องการ และข้อเสนอแนะ
A21: สร้าง Relationship | B21: ทำให้สาขา/VIP รู้สึกเป็นคนวงในและใกล้ผู้บริหาร
A22: ยกระดับช่องทางการตลาด | B22: สื่อสาร Asset Drive Center, Content, Campaign Support
A23: สร้าง Action Plan หลังงาน | B23: ให้ทุกฝ่ายมีสิ่งที่ต้องกลับไปทำต่ออย่างชัดเจน
A26: Speakers
A27: วิทยากร/เจ้าของช่วง | B27: บทบาทที่เหมาะสม
A28: CEO | B28: Vision, Direction, Deep Talk, Relationship
A29: ผู้บริหารฝ่ายการตลาด | B29: Brand, Campaign, Membership, Asset Drive, Agenda หลัก
A30: จัดซื้อ | B30: Product Roadmap, Supplier, Pricing Logic, New Product Plan
A31: R&D | B31: Demo, Test, Technical Explanation, Product Validation
A32: Product Manager | B32: Hidden Gems, Product Battle, Deep Dive
A33: Sale Manager | B33: How to Sell, Dealer/Branch Strategy
A34: Branch Manager | B34: Best Practice Sharing, Branch Reality
A35: IT / Digital Team | B35: Function Flow, Tracking, Dashboard, Asset Center
A36: Service Team | B36: After-sales, Installation, Common Problems
A37: VIP Dealer Guest | B37: Success Story, Dealer Voice
A38: Supplier Guest | B38: ใช้เฉพาะ Demo/Tech ไม่ให้พูดยาวขายตัวเอง
... A41: HR / Training | B41: Ice Breaking, Group Activity, Workshop Support
A44: Formats
A45: รูปแบบ Session
A46: Keynote
A47: Panel
A48: Workshop
...

Sheet How to use
A1: วิธีใช้ไฟล์ Agenda Planner
A3: 1 | B3: กรอกชื่องาน/วันที่/กลุ่มเป้าหมาย/จุดประสงค์หลักด้านบนของหน้า Agenda Planner
A4: 2 | B4: เลือกหัวข้อในคอลัมน์ C ระบบจะดึงหมวด รูปแบบ วิทยากร Detail และผลลัพธ์ให้อัตโนมัติ
A5: 3 | B5: ใส่เวลาเริ่ม-จบในคอลัมน์ F/G แล้วคอลัมน์ H จะคำนวณนาทีให้เอง
A6: 4 | B6: คอลัมน์ I และ N แก้ได้เองด้วย dropdown หากต้องการเปลี่ยนวิทยากรหรือกลุ่มที่เหมาะสม
A7: 5 | B7: ใช้คอลัมน์ O/P สำหรับหมายเหตุทีม Owner และสิ่งที่ต้อง follow-up
A8: 6 | B8: หน้า Data คือคลังหัวข้อและ dropdown สามารถเพิ่มหัวข้อใหม่ได้ แต่ควรเพิ่มให้อยู่ในช่วงรายการที่ตั้งไว้
A9: 7 | B9: ไฟล์นี้ตั้งใจให้เป็นต้นทางสำหรับทำ Brief/Agenda ต่อ ไม่ใช่แค่ตารางเวลา
